Workbook

Sheet Data Summary
A1: CURRENT STATISTICS
A2: Table 1: SEBI Registered Market Intermediaries/Institutions
A3: Table 2: Company-Wise Capital Raised through Public and Rights Issues (Equity)
A4: Table 3: Offers closed during the month under SEBI (SAST), 2011
A5: Table 4: Trends in Offers closed under SEBI (Substantial Acquisition of Shares and Takeover) Regulations, 2011
A6: Table 5: Consolidated Resource Mobilisation through Primary Market
A7: Table 6: Capital Raised from the Primary Market through Public and Rights Issues (Equity and Debt)
A8: Table 7: Industry-wise Classification of Capital Raised through Public and Rights Issues (Equity)
A9: Table 8: Sector-wise and Region-wise Distribution of Capital Mobilised through Public and Rights Issues (Equity)
A10: Table 9: Size-wise Classification of Capital Raised through Public and Rights Issues (Equity)
A11: Table 10: Capital Raised by Listed Companies from the Primary Market through QIPs
A12: Table 11: Preferential Allotments Listed at BSE, NSE and MSEI
... A75: Table 74: Macro Economic Indicators

Sheet 1
A1: Table 1: SEBI Registered Market Intermediaries/Institutions
A2: Market Intermediaries | B2: 2023-24 | C2: 45504
A3: Stock Exchanges (Cash Segment) | B3: 3 | C3: 3
A4: Stock Exchanges (Equity Derivatives Segment) | B4: 3 | C4: 3
A5: Stock Exchanges (Currency Derivatives Segment) | B5: 3 | C5: 3
A6: Stock Exchanges (Commodity Derivatives Segment) | B6: 4 | C6: 4
A7: Brokers (Cash Segment)
A8: BSE | B8: 1269 | C8: 1228
A9: NSE | B9: 1212 | C9: 1217
A10: MSEI | B10: 295 | C10: 290
A11: Brokers (Equity Derivatives Segment)
A12: BSE | B12: 903 | C12: 880
A13: NSE | B13: 1138 | C13: 1147
A14: MSEI | B14: 274 | C14: 269
A15: Brokers (Currency Derivatives Segment)
A16: BSE | B16: 560 | C16: 555
A17: NSE | B17: 754 | C17: 757
A18: MSEI | B18: 470 | C18: 465
A19: Brokers (Debt Segment)
A20: BSE | B20: 280 | C20: 282
A21: NSE | B21: 271 | C21: 277
A22: MSEI | B22: 14 | C22: 14
A23: Brokers (Commodity Derivatives Segment)
A24: MCX | B24: 546 | C24: 540
A25: NCDEX | B25: 250 | C25: 239
A26: ICEX | B26: 98 | C26: 98
A27: BSE | B27: 288 | C27: 290
A28: NSE | B28: 352 | C28: 365
A29: Corporate Brokers(Cash Segment)
A30: BSE | B30: 1092 | C30: 1070
A31: NSE | B31: 1093 | C31: 1098
A32: MSEI | B32: 270 | C32: 265
A33: Foreign Portfolio Investors (FPIs) | B33: 11219 | C33: 11483
A34: Custodians | B34: 17 | C34: 17
A35: Designated Depositories Participants (DDPs) | B35: 17 | C35: 17
A36: Depositories | B36: 2 | C36: 2
A37: Depository Participants
A38: NSDL | B38: 281 | C38: 285
A39: CDSL | B39: 580 | C39: 572
A40: Merchant Bankers | B40: 220 | C40: 225
...

Sheet 2
A1: Table 2: Company-Wise Capital Raised through Public and Rights Issues (Equity) (During the month of July 2024)
A2: Sl.No. | B2: Name of the Issuer/Company | C2: Date of Listing | D2: Type of Issue | E2: Number of Shares issued | F2: Face Value (₹ ) | G2: Premium Value (₹ ) | H2: Issue Price (₹ ) | I2: Amount raised (in crores) | L2: Oversubscribed (no. of times) | M2: Allocation in Net offer to public & Others (No. of shares) | Q2: Net offer to public*
I3: Fresh | J3: OFS | K3: Total | M3: QIB | N3: NII | O3: RII | P3: Others, if any (Market Maker & Reservation)
A4: 1 | B4: Mason Infratech Limited | C4: 45474 | D4: NSE SME IPO | E4: 4760000 | F4: 10 | G4: 54 | H4: 64 | I4: 30.464 | J4: 0 | K4: 30.464 | L4: 30.662 | M4: 2256000 | N4: 680000 | O4: 1584000 | P4: 240000 | Q4: 4520000
A5: 2 | B5: Shivalic Power Control Limited | C5: 45474 | D5: NSE SME IPO | E5: 6432000 | F5: 10 | G5: 90 | H5: 100 | I5: 64.32 | J5: 0 | K5: 64.32 | L5: 238.63 | M5: 3048000 | N5: 914400 | O5: 2133600 | P5: 336000 | Q5: 6096000
A6: 3 | B6: Sylvan Plyboard (India) Limited | C6: 45474 | D6: NSE SME IPO | E6: 5100000 | F6: 10 | G6: 45 | H6: 55 | I6: 28.05 | J6: 0 | K6: 28.05 | L6: 93.1 | M6: 0 | N6: 2222000 | O6: 2622000 | P6: 256000 | Q6: 4844000
A7: 4 | B7: Visaman Global Sales Limited | C7: 45474 | D7: NSE SME IPO | E7: 3732000 | F7: 10 | G7: 33 | H7: 43 | I7: 16.0476 | J7: 0 | K7: 16.0476 | L7: 37.48 | M7: 0 | N7: 1251000 | O7: 2289000 | P7: 192000 | Q7: 3540000
A8: 5 | B8: Akiko Global Services Limited | C8: 45475 | D8: NSE SME IPO | E8: 3001600 | F8: 10 | G8: 67 | H8: 77 | I8: 23.11232 | J8: 0 | K8: 23.11232 | L8: 35.25 | M8: 1424000 | N8: 428800 | O8: 998400 | P8: 150400 | Q8: 2851200
A9: 6 | B9: Divine Power Energy Limited | C9: 45475 | D9: NSE SME IPO | E9: 5688000 | F9: 10 | G9: 30 | H9: 40 | I9: 22.752 | J9: 0 | K9: 22.752 | L9: 472.44 | M9: 2700000 | N9: 810000 | O9: 1890000 | P9: 288000 | Q9: 5400000
A10: 7 | B10: Petro Carbon and Chemicals Limited | C10: 45475 | D10: NSE SME IPO | E10: 6617600 | F10: 10 | G10: 161 | H10: 171 | I10: 0 | J10: 113.16096 | K10: 113.16096 | L10: 93.55 | M10: 3092000 | N10: 928800 | O10: 2166400 | P10: 430400 | Q10: 6187200
A11: 8 | B11: Allied Blenders and Distillers Limited | C11: 45475 | D11: IPO | E11: 53390079 | F11: 2 | G11: 279 | H11: 281 | I11: 1000.2613 | J11: 499.99996 | K11: 1500.2612 | L11: 25.61 | M11: 26644795 | N11: 7993439 | O11: 18651357 | P11: 100488 | Q11: 53289591
A12: 9 | B12: Diensten Tech Limited | C12: 45476 | D12: NSE SME IPO | E12: 2208000 | F12: 10 | G12: 90 | H12: 100 | I12: 22.08 | J12: 0 | K12: 22.08 | L12: 50.47 | M12: 1047600 | N12: 315600 | O12: 734400 | P12: 110400 | Q12: 2097600
A13: 10 | B13: Vraj Iron and Steel Limited | C13: 45476 | D13: IPO | E13: 8260869 | F13: 10 | G13: 197 | H13: 207 | I13: 170.99999 | J13: 0 | K13: 170.99999 | L13: 133.9 | M13: 4130433 | N13: 1239131 | O13: 2891305 | P13: 0 | Q13: 8260869
A14: 11 | B14: Nephro Care India Limited | C14: 45478 | D14: NSE SME IPO | E14: 4584000 | F14: 10 | G14: 80 | H14: 90 | I14: 41.256 | J14: 0 | K14: 41.256 | L14: 712.36 | M14: 2145600 | N14: 644800 | O14: 1504000 | P14: 289600 | Q14: 4294400
A15: 12 | B15: Integra Essentia Limited | C15: 45478 | D15: Rights | E15: 153624538 | F15: 1 | G15: 2.25 | H15: 3.25 | I15: 49.92 | J15: 0 | K15: 49.92 | L15: 1.1907 | M15: 0 | N15: 0 | O15: 0 | P15: 0 | Q15: 0
... A45: 42 | B45: Srestha Finvest Limited | C45: 45504 | D45: Rights | E45: 240000000 | F45: 2 | G45: 0 | H45: 2 | I45: 48 | J45: 0 | K45: 48 | L45: 1.093 | M45: 0 | N45: 0 | O45: 0 | P45: 0 | Q45: 0
A47: *Shares issued by the Company are partly paid up but the information is provided considering the same as fully paid up.
A48: Net offer to Public = QIB (Including anchor) + RII + NII (Excluding Employee Reservation +Shareholder Reservation + Market maker)
A49: Source: SEBI

Sheet 3
A1: Table 3: Offers closed during July 2024 under SEBI (Substantial Acquisition of Shares and Takeover) Regulations, 2011
A2: Sl.No | B2: Target Company | C2: Acquirers/PACs | D2: Public Announcement Date | E2: Offer Opening Date | F2: Offer Closing Date | G2: Offer Size | I2: Offer Price (₹ ) per share | J2: Offer Size (₹ crore)
G3: No. of Shares | H3: Percent of Equity Capital
A4: 1 | B4: Consecutive Investments & Trading Company Limited | C4: M/s Birford Enterprises Private Limited | D4: 45322 | E4: 45471 | F4: 45484 | G4: 2081950 | H4: 26 | I4: 20 | J4: 4.1639
A5: 2 | B5: RKD Agri & Retail Limited | C5: Nilesh Malshi Savla and Meena Nilesh Savla | D5: 45344 | E5: 45474 | F5: 45485 | G5: 12889500 | H5: 26 | I5: 1.12 | J5: 1.443624
A6: 3 | B6: Continental Controls Limited | C6: Onelife Capital Advisors Limited | D6: 45357 | E6: 45474 | F6: 45485 | G6: 1598027 | H6: 26 | I6: 4 | J6: 0.6392108
A7: 4 | B7: Bangalore Fort Farms Limited | C7: Genesis Trade-Links Private Limited, Mr. Vikash Singh and Mrs. Nitu Singh | D7: 45364 | E7: 45474 | F7: 45485 | G7: 1247844 | H7: 26 | I7: 28.5 | J7: 3.5563554
A8: 5 | B8: Agro Tech Foods Limited | C8: ZEST HOLDING INVESTMENTS LIMITED, ZEST INVESTMENTS LIMITED, SAMARA CAPITAL PARTNERS FUND III LIMITED, INFINITY HOLDINGS, INFINITY HOLDINGS SIDECAR 1 | D8: 45351 | E8: 45484 | F8: 45498 | G8: 6336009 | H8: 26 | I8: 578.03 | J8: 366.24033
A9: 6 | B9: SOMA PAPERS AND INDUSTRIES LIMITED | C9: Mr. Narasimharao Anumala , Mr. Anumala Ramesh Choudary , Ms. Anupama Anumala | D9: 45364 | E9: 45484 | F9: 45498 | G9: 364559 | H9: 26 | I9: 12 | J9: 0.4374708
A10: 7 | B10: Ahmedabad Steelcraft Limited | C10: Mr. Rohit Pandey and Mr. Sunil Dutt Pandey | D10: 45415 | E10: 45485 | F10: 45499 | G10: 1063920 | H10: 26 | I10: 54 | J10: 5.745168
A11: 8 | B11: S&S Power Switchgear Limited | C11: Hamilton & Company Limited (“Acquirer”) and Sushil Kumar Jalan, Rekha Jalan, Ashish Jalan, Snehal Jalan, Ananya Jalan, Ashish Jalan Family Trust and Sushil K Jalan HUF (PACs). | D11: 45318 | E11: 45489 | F11: 45503 | G11: 3088947 | H11: 25.03 | I11: 155 | J11: 47.878678
A12: 9 | B12: Swadeshi Industries and Leasing Ltd. | C12: Mrs. Jayshree Radheshyam Sharma | D12: 45343 | E12: 45489 | F12: 45503 | G12: 2812667 | H12: 26 | I12: 2 | J12: 0.5625334
A13: 10 | B13: Trimurthi Limited | C13: Srinidhi Fine-Chemicals LLP and Mr. Vupparapalli Chandrasekhar Reddy | D13: 45356 | E13: 45489 | F13: 45503 | G13: 2652000 | H13: 26.65 | I13: 10 | J13: 2.652
A14: 11 | B14: Vikalp Securities Limited | C14: Deepakbhai Patel, Kamuben Patel | D14: 45397 | E14: 45489 | F14: 45503 | G14: 793500 | H14: 26 | I14: 25 | J14: 1.98375
A15: 12 | B15: Suncity Synthetics Limited | C15: Sumita Mishra | D15: 45398 | E15: 45489 | F15: 45503 | G15: 1285908 | H15: 26 | I15: 7 | J15: 0.9001356
A16: 13 | B16: Integra Switchgear Limited | C16: Northvale Capital Partners Private Limited | D16: 45334 | E16: 45489 | F16: 45503 | G16: 749216 | H16: 26 | I16: 12 | J16: 0.8990592
A18: Source: SEBI.

Sheet 4
A1: Table 4: Trends in Offers closed under SEBI (Substantial Acquisition of Shares and Takeover) Regulations, 2011
A2: Year / Month | B2: Open Offers
B3: Objectives | H3: Total
B4: Change in Control of Management | D4: Consolidation of Holdings | F4: Substantial Acquisition | H4: No. of Offers | I4: Amount (₹ crore)
B5: No. of Offers | C5: Amount (₹ crore) | D5: No. of Offers | E5: Amount (₹ crore) | F5: No. of Offers | G5: Amount (₹ crore)
A6: 2023-24 | B6: 1 | C6: 4.36 | D6: 1 | E6: 3.27 | F6: 71 | G6: 10243.92 | H6: 73 | I6: 10251.55
A7: 2024-25# | B7: =SUM(B8:B11) -> 21 | C7: =SUM(C8:C11) -> 477.4571 | D7: =SUM(D8:D11) -> 1 | E7: =SUM(E8:E11) -> 5.61 | F7: =SUM(F8:F11) -> 0 | G7: =SUM(G8:G11) -> 0 | H7: =SUM(H8:H11) -> 22 | I7: =SUM(I8:I11) -> 483.0671
A8: 45383 | B8: 4 | C8: 25.34 | D8: 1 | E8: 5.61 | F8: 0 | G8: 0 | H8: =SUM(B8,D8,F8) -> 5 | I8: =SUM(C8,E8,G8) -> 30.95
A9: =EOMONTH(A8,1) -> 45443 | B9: 1 | C9: 4.98 | D9: 0 | E9: 0 | F9: 0 | G9: 0 | H9: 1 | I9: 4.98
A10: =EOMONTH(A9,1) -> 45473 | B10: 3 | C10: 10.0371 | D10: 0 | E10: 0 | F10: 0 | G10: 0 | H10: =SUM(B10,D10,F10) -> 3 | I10: =SUM(C10,E10,G10) -> 10.0371
A11: =EOMONTH(A10,1) -> 45504 | B11: 13 | C11: 437.1 | D11: 0 | E11: 0 | F11: 0 | G11: 0 | H11: =SUM(B11,D11,F11) -> 13 | I11: =SUM(C11,E11,G11) -> 437.1
A12: ="# indicates as on "&TEXT('1'!$C$2,"mmmm dd, yyyy") -> # indicates as on July 31, 2024
A13: *In instances where offers have more than one objective, the issue is classified only under one of the same.
A14: Data is compiled based on offer closing date
A15: Source: SEBI.

Sheet 5
A1: Table 5: Consolidated Resource Mobilisation through Primary markets | U1: =U6+S6 -> 1957.28
A2: Modes of Fund Raising | B2: 2023-24 | F2: ="2024-25 (upto "&TEXT('1'!$C$2,"mmmm dd, yyyy")&")" -> 2024-25 (upto July 31, 2024) | J2: 45412 | N2: =EOMONTH(J2,1) -> 45443 | R2: =EOMONTH(N2,1) -> 45473 | V2: =EOMONTH(R2,1) -> 45504
B3: Financial Sector | D3: Non-Financial Sector | F3: Financial Sector | H3: Non-Financial Sector | J3: Financial Sector | L3: Non-Financial Sector | N3: Financial Sector | P3: Non-Financial Sector | R3: Financial Sector | T3: Non-Financial Sector | V3: Financial Sector | X3: Non-Financial Sector
B4: No. of Issues | C4: Amount (Rs.crore) | D4: No. of Issues | E4: Amount (Rs.crore) | F4: No. of Issues | G4: Amount (Rs.crore) | H4: No. of Issues | I4: Amount (Rs.crore) | J4: No. of Issues | K4: Amount (Rs.crore) | L4: No. of Issues | M4: Amount (Rs.crore) | N4: No. of Issues | O4: Amount (Rs.crore) | P4: No. of Issues | Q4: Amount (Rs.crore) | R4: No. of Issues | S4: Amount (Rs.crore) | T4: No. of Issues | U4: Amount (Rs.crore) | V4: No. of Issues | W4: Amount (Rs.crore) | X4: No. of Issues | Y4: Amount (Rs.crore)
A5: Equity Issues
A6: A. IPOs (Main Board) | B6: 9 | C6: 7506.2741 | D6: 67 | E6: 54353.573 | F6: 3 | G6: 5746.6459 | H6: 15 | I6: 15749.873 | J6: 0 | K6: 0 | L6: 3 | M6: 5054.67 | N6: 2 | O6: 5614.6459 | P6: 3 | Q6: 3991.4846 | R6: 1 | S6: 132 | T6: 4 | U6: 1825.28 | V6: 0 | W6: 0 | X6: 5 | Y6: =SUM(Y7:Y8) -> 4878.4382
A7: i) OFS Component | B7: - | C7: 2942.2088 | D7: - | E7: 30160.031 | F7: - | G7: 3489.6458 | H7: - | I7: 10273.338 | J7: - | K7: 0 | L7: - | M7: 4624.4737 | N7: - | O7: 3489.6458 | P7: - | Q7: 2703.4941 | R7: - | S7: 0 | T7: - | U7: 1180.2934 | V7: - | W7: 0 | X7: - | Y7: 1765.0769
A8: ii) Fresh Capital Raising Component | B8: - | C8: 4564.8985 | D8: - | E8: 24200.779 | F8: - | G8: 2257.5513 | H8: - | I8: 5477.6259 | J8: - | K8: 0 | L8: - | M8: 430.19997 | N8: - | O8: 2125.5513 | P8: - | Q8: 1288.9614 | R8: - | S8: 132 | T8: - | U8: 645.10323 | V8: - | W8: 0 | X8: - | Y8: 3113.3612
A9: B. IPO (SME) | B9: 3 | C9: 121.60544 | D9: 193 | E9: 5973.8595 | F9: 1 | G9: 32.52 | H9: 85 | I9: 2912.7608 | J9: 0 | K9: 0 | L9: 23 | M9: 672.70852 | N9: 0 | O9: 0 | P9: 21 | Q9: 527.21852 | R9: 1 | S9: 32.52 | T9: 16 | U9: 530.818 | V9: 0 | W9: 0 | X9: 25 | Y9: =SUM(Y10:Y11) -> 1182.0157
A10: i) OFS Component | B10: - | C10: 6.08 | D10: - | E10: 322.28525 | F10: - | G10: 9.288 | H10: - | I10: 212.01756 | J10: - | K10: 0 | L10: - | M10: 0 | N10: - | O10: 0 | P10: - | Q10: 6.5988 | R10: - | S10: 9.288 | T10: - | U10: 48.536 | V10: - | W10: 0 | X10: - | Y10: 156.88276
A11: ii) Fresh Capital Raising Component | B11: - | C11: 115.52356 | D11: - | E11: 5651.7001 | F11: - | G11: 23.232 | H11: - | I11: 2700.7885 | J11: - | K11: 0 | L11: - | M11: 672.72668 | N11: - | O11: 0 | P11: - | Q11: 520.62464 | R11: - | S11: 23.232 | T11: - | U11: 482.3042 | V11: - | W11: 0 | X11: - | Y11: 1025.133
A12: C. IPO (Total) [A+B] | B12: 12 | C12: 7627.8795 | D12: 260 | E12: 60327.433 | F12: 4 | G12: 5779.1659 | H12: 100 | I12: 18662.634 | J12: =J9+J6 -> 0 | K12: =K9+K6 -> 0 | L12: =L9+L6 -> 26 | M12: =M9+M6 -> 5727.3785 | N12: =N9+N6 -> 2 | O12: =O9+O6 -> 5614.6459 | P12: =P9+P6 -> 24 | Q12: =Q9+Q6 -> 4518.7031 | ... Y12: =Y9+Y6 -> 6060.4539
A13: i) OFS Component (Total) | B13: - | C13: 2948.2888 | D13: - | E13: 30482.317 | F13: - | G13: 3498.9338 | H13: - | I13: 10485.356 | J13: - | K13: =K7+K10 -> 0 | L13: - | M13: =M7+M10 -> 4624.4737 | N13: - | O13: =O7+O10 -> 3489.6458 | P13: - | Q13: =Q7+Q10 -> 2710.0929 | R13: - | S13: =S7+S10 -> 9.288 | T13: - | U13: =U7+U10 -> 1228.8294 | V13: - | W13: =W7+W10 -> 0 | X13: - | Y13: =Y7+Y10 -> 1921.9597
A14: ii) Fresh Capital Raising Component (Total) | B14: - | C14: 4680.422 | D14: - | E14: 29852.479 | F14: - | G14: 2280.7833 | H14: - | I14: 8178.4143 | J14: - | K14: =K8+K11 -> 0 | L14: - | M14: =M11+M8 -> 1102.9267 | N14: - | O14: =O8+O11 -> 2125.5513 | P14: - | Q14: =Q11+Q8 -> 1809.5861 | R14: - | S14: =S8+S11 -> 155.232 | T14: - | U14: =U11+U8 -> 1127.4074 | V14: - | W14: =W8+W11 -> 0 | X14: - | Y14: =Y11+Y8 -> 4138.4942
A15: D. FPO in the Main Board | B15: 0 | C15: 0 | D15: 0 | E15: 0 | F15: 0 | G15: 0 | H15: 2 | I15: 18149.992 | J15: =J16+J17 -> 0 | K15: =K16+K17 -> 0 | L15: 1 | M15: 18000 | N15: =N16+N17 -> 0 | O15: =O16+O17 -> 0 | P15: =P16+P17 -> 0 | Q15: =Q16+Q17 -> 0 | R15: =R16+R17 -> 0 | S15: =S16+S17 -> 0 | T15: =T16+T17 -> 0 | U15: =U16+U17 -> 0 | ... Y15: =Y16+Y17 -> 149.9925
A16: i) OFS Component | B16: 0 | C16: 0 | D16: 0 | E16: 0 | F16: 0 | G16: 0 | H16: 0 | I16: 0 | J16: 0 | K16: 0 | L16: 0 | M16: 0 | N16: 0 | O16: 0 | P16: 0 | Q16: 0 | R16: 0 | S16: 0 | T16: 0 | U16: 0 | V16: 0 | W16: 0 | X16: 0 | Y16: 0
A17: ii) Fresh Capital Raising Component | B17: 0 | C17: 0 | D17: 0 | E17: 0 | F17: 0 | G17: 0 | H17: 2 | I17: 18149.992 | J17: 0 | K17: 0 | L17: 1 | M17: 18000 | N17: 0 | O17: 0 | P17: 0 | Q17: 0 | R17: 0 | S17: 0 | T17: 0 | U17: 0 | V17: 0 | W17: 0 | X17: 1 | Y17: 149.9925
A18: E. FPO in the SME Segment | B18: 0 | C18: 0 | D18: 1 | E18: 27 | F18: 0 | G18: 0 | H18: 0 | I18: 0 | J18: =J19+J20 -> 0 | K18: =K19+K20 -> 0 | L18: =L19+L20 -> 0 | M18: =M19+M20 -> 0 | N18: =N19+N20 -> 0 | O18: =O19+O20 -> 0 | P18: =P19+P20 -> 0 | Q18: =Q19+Q20 -> 0 | ... Y18: =Y19+Y20 -> 0
A19: i) OFS Component | B19: 0 | C19: 0 | D19: 0 | E19: 0 | F19: 0 | G19: 0 | H19: 0 | I19: 0 | J19: 0 | K19: 0 | L19: 0 | M19: 0 | N19: 0 | O19: 0 | P19: 0 | Q19: 0 | R19: 0 | S19: 0 | T19: 0 | U19: 0 | V19: 0 | W19: 0 | X19: 0 | Y19: 0
A20: ii) Fresh Capital Raising Component | B20: 0 | C20: 0 | D20: 1 | E20: 27 | F20: 0 | G20: 0 | H20: 0 | I20: 0 | J20: 0 | K20: 0 | L20: 0 | M20: 0 | N20: 0 | O20: 0 | P20: 0 | Q20: 0 | R20: 0 | S20: 0 | T20: 0 | U20: 0 | V20: 0 | W20: 0 | X20: 0 | Y20: 0
A21: F. FPO (Total) [D+E] | B21: 0 | C21: 0 | D21: 1 | E21: 27 | F21: 0 | G21: 0 | H21: 2 | I21: 18149.992 | J21: =J18+J15 -> 0 | K21: =K18+K15 -> 0 | L21: =L18+L15 -> 1 | M21: =M18+M15 -> 18000 | N21: =N18+N15 -> 0 | O21: =O18+O15 -> 0 | P21: =P18+P15 -> 0 | Q21: =Q18+Q15 -> 0 | ... Y21: =Y18+Y15 -> 149.9925
A22: i) OFS Component | B22: 0 | C22: 0 | D22: 0 | E22: 0 | F22: 0 | G22: 0 | H22: 0 | I22: 0 | J22: =J16+J19 -> 0 | K22: =K16+K19 -> 0 | L22: =L16+L19 -> 0 | M22: =M16+M19 -> 0 | N22: =N16+N19 -> 0 | O22: =O16+O19 -> 0 | P22: =P16+P19 -> 0 | Q22: =Q16+Q19 -> 0 | ... Y22: =Y16+Y19 -> 0
A23: ii) Fresh Capital Raising Component | B23: 0 | C23: 0 | D23: 1 | E23: 27 | F23: 0 | G23: 0 | H23: 2 | I23: 18149.992 | J23: =J20+J17 -> 0 | K23: =K20+K17 -> 0 | L23: =L20+L17 -> 1 | M23: =M20+M17 -> 18000 | N23: =N20+N17 -> 0 | O23: =O20+O17 -> 0 | P23: =P20+P17 -> 0 | Q23: =Q20+Q17 -> 0 | ... Y23: =Y20+Y17 -> 149.9925
A24: G. Total Public Issues in equity (C+F) | B24: =B12+B21 -> 12 | C24: =C12+C21 -> 7627.8795 | D24: =D12+D21 -> 261 | E24: =E12+E21 -> 60354.433 | F24: 4 | G24: 5779.1659 | H24: 102 | I24: 36812.626 | J24: =J12+J21 -> 0 | K24: =K12+K21 -> 0 | L24: =L12+L21 -> 27 | M24: =M12+M21 -> 23727.379 | N24: =N12+N21 -> 2 | O24: =O12+O21 -> 5614.6459 | P24: =P12+P21 -> 24 | Q24: =Q12+Q21 -> 4518.7031 | ... Y24: =Y12+Y21 -> 6210.4464
A25: i) OFS Component (Total) | B25: - | C25: =C13+C22 -> 2948.2888 | D25: - | E25: =E13+E22 -> 30482.317 | F25: - | G25: 3498.9338 | H25: - | I25: 10485.356 | J25: - | K25: =K13+K22 -> 0 | L25: - | M25: =M13+M22 -> 4624.4737 | N25: - | O25: =O13+O22 -> 3489.6458 | P25: - | Q25: =Q13+Q22 -> 2710.0929 | R25: - | S25: =S13+S22 -> 9.288 | T25: - | U25: =U13+U22 -> 1228.8294 | V25: - | W25: =W13+W22 -> 0 | X25: - | Y25: =Y13+Y22 -> 1921.9597
A26: ii) Fresh Capital Raising Component (Total) | B26: - | C26: =C14+C23 -> 4680.422 | D26: - | E26: =E14+E23 -> 29879.479 | F26: - | G26: 2280.7833 | H26: - | I26: 26328.407 | J26: - | K26: =K14+K23 -> 0 | L26: - | M26: =M14+M23 -> 19102.927 | N26: - | O26: =O14+O23 -> 2125.5513 | P26: - | Q26: =Q14+Q23 -> 1809.5861 | R26: - | S26: =S14+S23 -> 155.232 | T26: - | U26: =U14+U23 -> 1127.4074 | V26: - | W26: =W14+W23 -> 0 | X26: - | Y26: =Y14+Y23 -> 4288.4867
A27: H. Rights Issue | B27: 9 | C27: 7241.9913 | D27: 58 | E27: 7868.2127 | F27: 6 | G27: 2594.4881 | H27: 41 | I27: 5045.4625 | J27: =SUM(J28:J29) -> 2 | K27: =SUM(K28:K29) -> 1184.13 | L27: =SUM(L28:L29) -> 6 | M27: =SUM(M28:M29) -> 459.05831 | N27: =SUM(N28:N29) -> 1 | O27: =SUM(O28:O29) -> 1271.8281 | P27: =SUM(P28:P29) -> 11 | Q27: =SUM(Q28:Q29) -> 883.40641 | ... Y27: =SUM(Y28:Y29) -> 2742.9477
A28: i)MainBoard Companies | B28: 8 | C28: 7215.1313 | D28: 50 | E28: 7661.5576 | F28: 6 | G28: 2594.4881 | H28: 32 | I28: 4234.7065 | J28: 2 | K28: 1184.13 | L28: 4 | M28: 425.20831 | N28: 1 | O28: 1271.8281 | P28: 9 | Q28: 454.31841 | R28: 2 | S28: 90.53 | T28: 12 | U28: 949.5 | V28: 1 | W28: 48 | X28: 7 | Y28: 2405.6798
A29: ii) SME / IGP Companies | B29: 1 | C29: 26.86 | D29: 8 | E29: 206.65512 | F29: 0 | G29: 0 | H29: 9 | I29: 810.75595 | J29: 0 | K29: 0 | L29: 2 | M29: 33.85 | N29: 0 | O29: 0 | P29: 2 | Q29: 429.088 | R29: 0 | S29: 0 | T29: 2 | U29: 10.55 | V29: 0 | W29: 0 | X29: 3 | Y29: 337.26795
A30: I. Preferential Issue | B30: 69 | C30: 7021.1733 | D30: 620 | E30: 38134.004 | F30: 46 | G30: 8282.4075 | H30: 299 | I30: 35732.382 | J30: =J31+J32 -> 8 | K30: =K31+K32 -> 120.31 | L30: =L31+L32 -> 99 | M30: =M31+M32 -> 7581.8799 | N30: =N31+N32 -> 15 | O30: =O31+O32 -> 2614.4275 | P30: =P31+P32 -> 99 | Q30: =Q31+Q32 -> 22378.766 | ... Y30: =Y31+Y32 -> 976.80252
A31: i)MainBoard Companies | B31: 69 | C31: 7021.1733 | D31: 564 | E31: 37516.552 | F31: 45 | G31: 8268.3975 | H31: 262 | I31: 35130.317 | J31: 8 | K31: 120.31 | L31: 85 | M31: 7298.8208 | N31: 15 | O31: 2614.4275 | P31: 92 | Q31: 22307.354 | R31: 12 | S31: 2186.25 | T31: 42 | U31: 4664.8296 | V31: 10 | W31: 3347.41 | X31: 43 | Y31: 859.31226
A32: ii) SME / IGP Companies | B32: 0 | C32: 0 | D32: 56 | E32: 617.45168 | F32: 1 | G32: 14.01 | H32: 37 | I32: 602.06513 | J32: 0 | K32: 0 | L32: 14 | M32: 283.05913 | N32: 0 | O32: 0 | P32: 7 | Q32: 71.41169 | R32: 1 | S32: 14.01 | T32: 6 | U32: 130.10405 | X32: 10 | Y32: 117.49026
A33: J. QIPs/IPPs | B33: 15 | C33: 40320.47 | D33: 46 | E33: 28651.001 | F33: 3 | G33: 2599.9998 | H33: 27 | I33: 28385.677 | J33: =J34+J35 -> 2 | K33: =K34+K35 -> 2099.9999 | L33: =L34+L35 -> 9 | M33: =M34+M35 -> 9371.7329 | N33: =N34+N35 -> 0 | O33: =O34+O35 -> 0 | P33: =P34+P35 -> 2 | Q33: =Q34+Q35 -> 3039.9999 | ... Y33: =Y34+Y35 -> 13699.105
A34: i)MainBoard Companies | B34: 15 | C34: 40320.47 | D34: 44 | E34: 28534.464 | F34: 3 | G34: 2599.9998 | H34: 26 | I34: 28360.837 | J34: 2 | K34: 2099.9999 | L34: 9 | M34: 9371.7329 | N34: 0 | O34: 0 | P34: 2 | Q34: 3039.9999 | R34: 1 | S34: 499.9999 | T34: 4 | U34: 2249.9997 | V34: 0 | W34: 0 | X34: 11 | Y34: 13699.105
A35: ii) SME / IGP Companies | B35: 0 | C35: 0 | D35: 2 | E35: 116.53785 | F35: 0 | G35: 0 | H35: 1 | I35: 24.84 | J35: 0 | K35: 0 | L35: 0 | M35: 0 | N35: 0 | O35: 0 | P35: 0 | Q35: 0 | R35: 0 | S35: 0 | T35: 1 | U35: 24.84 | V35: 0 | W35: 0 | X35: 0 | Y35: 0
A36: K. OFS through Exchanges | B36: 4 | C36: 1652.728 | D36: 47 | E36: 22881.828 | F36: 0 | G36: 0 | H36: 6 | I36: 1186.0239 | J36: =J37+J38 -> 0 | K36: =K37+K38 -> 0 | L36: =L37+L38 -> 1 | M36: =M37+M38 -> 14.312002 | N36: =N37+N38 -> 0 | O36: =O37+O38 -> 0 | P36: =P37+P38 -> 1 | Q36: =Q37+Q38 -> 219.95773 | ... Y36: =Y37+Y38 -> 860.74329
A37: i)Mainboard companies | B37: 4 | C37: 1652.728 | D37: 47 | E37: 22881.828 | F37: 0 | G37: 0 | H37: 6 | I37: 1186.0239 | J37: 0 | K37: 0 | L37: 1 | M37: 14.312002 | N37: 0 | O37: 0 | P37: 1 | Q37: 219.95773 | R37: 0 | S37: 0 | T37: 1 | U37: 91.01092 | V37: 0 | W37: 0 | X37: 3 | Y37: 860.74329
A38: ii)SME/IGP companies | B38: 0 | C38: 0 | D38: 0 | E38: 0 | F38: 0 | G38: 0 | H38: 0 | I38: 0 | J38: 0 | K38: 0 | L38: 0 | M38: 0 | N38: 0 | O38: 0 | P38: 0 | Q38: 0 | R38: 0 | S38: 0 | T38: 0 | U38: 0 | V38: 0 | W38: 0 | X38: 0 | Y38: 0
A39: L. Total Equity raised | B39: =B24+B27+B30+B33+B36 -> 109 | C39: =C24+C27+C30+C33+C36 -> 63864.242 | D39: =D24+D27+D30+D33+D36 -> 1032 | E39: =E24+E27+E30+E33+E36 -> 157889.48 | F39: 59 | G39: 19256.061 | H39: 475 | I39: 107162.17 | J39: =J24+J27+J30+J33+J36 -> 12 | K39: =K24+K27+K30+K33+K36 -> 3404.4399 | L39: =L24+L27+L30+L33+L36 -> 142 | M39: =M24+M27+M30+M33+M36 -> 41154.362 | N39: =N24+N27+N30+N33+N36 -> 18 | O39: =O24+O27+O30+O33+O36 -> 9500.9015 | P39: =P24+P27+P30+P33+P36 -> 137 | Q39: =Q24+Q27+Q30+Q33+Q36 -> 31040.833 | ... Y39: =Y24+Y27+Y30+Y33+Y36 -> 24490.045
A40: i) OFS Component (Total) G(i)+K | B40: - | C40: =C25+C36 -> 4601.0168 | D40: - | E40: =E25+E36 -> 53364.145 | F40: - | G40: 3498.9338 | H40: - | I40: 11671.38 | J40: - | K40: =K25+K36 -> 0 | L40: - | M40: =M25+M36 -> 4638.7857 | N40: - | O40: =O25+O36 -> 3489.6458 | P40: - | Q40: =Q25+Q36 -> 2930.0506 | R40: - | S40: =S25+S36 -> 9.288 | T40: - | U40: =U25+U36 -> 1319.8403 | V40: - | W40: =W25+W36 -> 0 | X40: - | Y40: =Y25+Y36 -> 2782.703
...

Sheet 6
A1: Table 6: Capital Raised from the Primary Market through Public and Rights Issues
A2: Year / Month | B2: Total (Equity+Debt) | D2: Equity | N2: Debt
D3: IPOs (Mainboard) | F3: IPOs (SME issues) | H3: IPOs (Total) | J3: Rights | L3: FPOs | N3: Public issues
B4: No. of issues | C4: Amount ( ₹ crore) | D4: No. of issues | E4: Amount ( ₹ crore) | F4: No. of issues | G4: Amount ( ₹ crore) | H4: No. of issues | I4: Amount ( ₹ crore) | J4: No. of issues | K4: Amount ( ₹ crore) | L4: No. of issues | M4: Amount ( ₹ crore) | N4: No. of issues | O4: Amount ( ₹ crore)
A5: 2023-24 | B5: 385 | C5: 102259.42 | D5: 76 | E5: 61859.847 | F5: 196 | G5: 6095.4649 | H5: 272 | I5: 67955.312 | J5: 67 | K5: 15110.204 | L5: 1 | M5: 27 | N5: 45 | O5: 19166.9
A6: 2024-25# | B6: =SUM(B7:B10) -> 165 | C6: =SUM(C7:C10) -> 52947.409 | D6: =SUM(D7:D10) -> 18 | E6: =SUM(E7:E10) -> 21496.26 | F6: =SUM(F7:F10) -> 86 | G6: =SUM(G7:G10) -> 2945.2718 | H6: =D6+F6 -> 104 | I6: =E6+G6 -> 24441.532 | J6: =SUM(J7:J10) -> 47 | K6: =SUM(K7:K10) -> 7639.927 | L6: =SUM(L7:L10) -> 2 | M6: =SUM(M7:M10) -> 18149.99 | N6: =SUM(N7:N10) -> 12 | O6: =SUM(O7:O10) -> 2715.96
A7: 45383 | B7: =H7+J7+L7+N7 -> 39 | C7: =I7+K7+M7+O7 -> 26057.317 | D7: 3 | E7: 5054.67 | F7: 23 | G7: 672.70852 | H7: =D7+F7 -> 26 | I7: =E7+G7 -> 5727.3785 | J7: 8 | K7: 1643.1883 | L7: 1 | M7: 18000 | N7: 4 | O7: 686.75
A8: 45443 | B8: =H8+J8+L8+N8 -> 41 | C8: =I8+K8+M8+O8 -> 13495.543 | D8: 5 | E8: 9606.1304 | F8: 21 | G8: 527.21852 | H8: =D8+F8 -> 26 | I8: =E8+G8 -> 10133.349 | J8: 12 | K8: 2155.2345 | L8: 0 | M8: 0 | N8: 3 | O8: 1206.96
A9: 45473 | B9: =H9+J9+L9+N9 -> 41 | C9: =I9+K9+M9+O9 -> 4131.448 | D9: 5 | E9: 1957.28 | F9: 17 | G9: 563.338 | H9: =D9+F9 -> 22 | I9: =E9+G9 -> 2520.618 | J9: 16 | K9: 1050.58 | L9: 0 | M9: 0 | N9: 3 | O9: 560.25
A10: 45504 | B10: =H10+J10+L10+N10 -> 44 | C10: =I10+K10+M10+O10 -> 9263.1009 | D10: 5 | E10: 4878.18 | F10: 25 | G10: 1182.0067 | H10: =D10+F10 -> 30 | I10: =E10+G10 -> 6060.1867 | J10: 11 | K10: 2790.9242 | L10: 1 | M10: 149.99 | N10: 2 | O10: 262
A11: Notes:
A12: 1. Equity data on IPO issues are categorised based on the listing date .
A13: 2. Debt issues are classified based on closing date of the issue
A14: ="# indicates as on "&TEXT('1'!$C$2,"mmmm dd, yyyy") -> # indicates as on July 31, 2024
A15: Source: SEBI.

Sheet 7
A1: Table 7: Industry-wise Classification of Capital Raised through Public and Rights Issues (Equity)
A2: Macro Economic Sector | B2: Sector | C2: Industry | D2: 2023-24 | F2: 2024-25 (Till July-24) | H2: 45383 | J2: =EOMONTH(H2,1) -> 45443 | L2: =EOMONTH(J2,1) -> 45473 | N2: =EOMONTH(L2,1) -> 45504
D3: No. of issues | E3: Amount ( ₹ crore) | F3: No. of issues | G3: Amount ( ₹ crore) | H3: No. of issues | I3: Amount ( ₹ crore) | J3: No. of issues | K3: Amount ( ₹ crore) | L3: No. of issues | M3: Amount ( ₹ crore) | N3: No. of issues | O3: Amount ( ₹ crore)
A4: Commodities | B4: Chemicals | C4: Chemicals & Petrochemicals | D4: 7 | E4: 615.83574 | F4: 5 | G4: 209.7716 | H4: 0 | I4: 0 | J4: 2 | K4: 60.4916 | L4: 3 | M4: 149.28 | N4: 0 | O4: 0
C5: Fertilizers & Agrochemicals | D5: 2 | E5: 170.5403 | F5: 1 | G5: 44.676 | H5: 0 | I5: 0 | J5: 0 | K5: 0 | L5: 0 | M5: 0 | N5: 1 | O5: 44.676
B6: Construction Materials | C6: Cement & Cement Products | D6: 2 | E6: 4447.0124 | F6: 1 | G6: 400 | H6: 0 | I6: 0 | J6: 1 | K6: 400 | L6: 0 | M6: 0 | N6: 0 | O6: 0
C7: Other Construction Materials | D7: 1 | E7: 49.98 | F7: 0 | G7: 0 | H7: 0 | I7: 0 | J7: 0 | K7: 0 | L7: 0 | M7: 0 | N7: 0 | O7: 0
B8: Metals & Mining | C8: Ferrous Metals | D8: 1 | E8: 42.69264 | F8: 1 | G8: 170.99999 | H8: 0 | I8: 0 | J8: 0 | K8: 0 | L8: 0 | M8: 0 | N8: 1 | O8: 170.99999
C9: Non - Ferrous Metals | D9: 0 | E9: 0 | F9: 0 | G9: 0 | H9: 0 | I9: 0 | J9: 0 | K9: 0 | L9: 0 | M9: 0 | N9: 0 | O9: 0
C10: Diversified Metals | D10: 0 | E10: 0 | F10: 0 | G10: 0 | H10: 0 | I10: 0 | J10: 0 | K10: 0 | L10: 0 | M10: 0 | N10: 0 | O10: 0
C11: Minerals & Mining | D11: 0 | E11: 0 | F11: 1 | G11: 113.16096 | H11: 0 | I11: 0 | J11: 0 | K11: 0 | L11: 0 | M11: 0 | N11: 1 | O11: 113.16096
C12: Metals & Minerals Trading | D12: 1 | E12: 37.533577 | F12: 0 | G12: 0 | H12: 0 | I12: 0 | J12: 0 | K12: 0 | L12: 0 | M12: 0 | N12: 0 | O12: 0
B13: Forest Materials | C13: Paper, Forest & Jute Products | D13: 2 | E13: 77.48 | F13: 2 | G13: 84.927345 | H13: 0 | I13: 0 | J13: 1 | K13: 45.107345 | L13: 0 | M13: 0 | N13: 1 | O13: 39.82
A14: Consumer Discretionary | B14: Automobile and Auto Components | C14: Automobiles | D14: 1 | E14: 601.55 | F14: 1 | G14: 115.64 | H14: 0 | I14: 0 | J14: 0 | K14: 0 | L14: 0 | M14: 0 | N14: 1 | O14: 115.64
C15: Auto Components | D15: 3 | E15: 914.20792 | F15: 2 | G15: 79.1356 | H15: 1 | I15: 53.89 | J15: 1 | K15: 25.2456 | L15: 0 | M15: 0 | N15: 0 | O15: 0
B16: Consumer Durables | C16: Consumer Durables | D16: 22 | E16: 4644.4649 | F16: 11 | G16: 817.74036 | H16: 5 | I16: 141.13037 | J16: 1 | K16: 15 | L16: 4 | M16: 633.56 | N16: 1 | O16: 28.05
B17: Textiles | C17: Textiles & Apparels | D17: 14 | E17: 279.0674 | F17: 7 | G17: 199.92131 | H17: 1 | I17: 44.741308 | J17: 2 | K17: 28.87 | L17: 3 | M17: 76.39 | N17: 1 | O17: 49.92
B18: Media, Entertainment & Publication | C18: Media | D18: 5 | E18: 555.205 | F18: 1 | G18: 8.4816 | H18: 0 | I18: 0 | J18: 1 | K18: 8.4816 | L18: 0 | M18: 0 | N18: 0 | O18: 0
C19: Entertainment | D19: 6 | E19: 240.97613 | F19: 1 | G19: 14.25152 | H19: 1 | I19: 14.25152 | J19: 0 | K19: 0 | L19: 0 | M19: 0 | N19: 0 | O19: 0
C20: Printing & Publication | D20: 0 | E20: 0 | F20: 1 | G20: 45.9 | H20: 0 | I20: 0 | J20: 0 | K20: 0 | L20: 0 | M20: 0 | N20: 1 | O20: 45.9
B21: Realty | C21: Realty | D21: 6 | E21: 1256.2571 | F21: 2 | G21: 2029.484 | H21: 0 | I21: 0 | J21: 0 | K21: 0 | L21: 0 | M21: 0 | N21: 2 | O21: 2029.484
B22: Consumer Services | C22: Leisure Services | D22: 5 | E22: 4895.93 | F22: 4 | G22: 2316.5109 | H22: 1 | I22: 16.4736 | J22: 1 | K22: 1550.8093 | L22: 2 | M22: 749.228 | N22: 0 | O22: 0
C23: Other Consumer Services | D23: 7 | E23: 215.69184 | F23: 1 | G23: 6.81 | H23: 0 | I23: 0 | J23: 0 | K23: 0 | L23: 1 | M23: 6.81 | N23: 0 | O23: 0
C24: Retailing | D24: 12 | E24: 3584.8556 | F24: 1 | G24: 13.53 | H24: 0 | I24: 0 | J24: 1 | K24: 13.53 | L24: 0 | M24: 0 | N24: 0 | O24: 0
A25: Energy | B25: Oil, Gas & Consumable Fuels | C25: Gas | D25: 2 | E25: 558.4 | F25: 0 | G25: 0 | H25: 0 | I25: 0 | J25: 0 | K25: 0 | L25: 0 | M25: 0 | N25: 0 | O25: 0
C26: Oil | D26: 0 | E26: 0 | F26: 0 | G26: 0 | H26: 0 | I26: 0 | J26: 0 | K26: 0 | L26: 0 | M26: 0 | N26: 0 | O26: 0
C27: Petroleum Products | D27: 2 | E27: 520.93 | F27: 1 | G27: 6.3 | H27: 1 | I27: 6.3 | J27: 0 | K27: 0 | L27: 0 | M27: 0 | N27: 0 | O27: 0
C28: Consumable Fuels | D28: 0 | E28: 0 | F28: 0 | G28: 0 | H28: 0 | I28: 0 | J28: 0 | K28: 0 | L28: 0 | M28: 0 | N28: 0 | O28: 0
A29: Fast Moving Consumer Goods | B29: Fast Moving Consumer Goods | C29: Agricultural Food & other Products | D29: 8 | E29: 324.42033 | F29: 8 | G29: 778.04512 | H29: 2 | I29: 76.0656 | J29: 2 | K29: 54.7 | L29: 2 | M29: 86.12952 | N29: 2 | O29: 561.15
C30: Beverages | D30: 1 | E30: 48.9433 | F30: 2 | G30: 1521.78 | H30: 1 | I30: 21.78 | J30: 0 | K30: 0 | L30: 0 | M30: 0 | N30: 1 | O30: 1500
C31: Cigarettes & Tobacco Products | D31: 1 | E31: 16.07 | F31: 0 | G31: 0 | H31: 0 | I31: 0 | J31: 0 | K31: 0 | L31: 0 | M31: 0 | N31: 0 | O31: 0
C32: Food Products | D32: 13 | E32: 1596.7931 | F32: 7 | G32: 166.284 | H32: 2 | I32: 32.1 | J32: 2 | K32: 44.324 | L32: 2 | M32: 77.14 | N32: 1 | O32: 12.72
C33: Personal Products | D33: 1 | E33: 1701.44 | F33: 1 | G33: 19.464 | H33: 0 | I33: 0 | J33: 0 | K33: 0 | L33: 0 | M33: 0 | N33: 1 | O33: 19.464
C34: Household Products | D34: 2 | E34: 1793 | F34: 1 | G34: 24.54 | H34: 0 | I34: 0 | J34: 0 | K34: 0 | L34: 0 | M34: 0 | N34: 1 | O34: 24.54
C35: Diversified FMCG | D35: 0 | E35: 0 | F35: 0 | G35: 0 | H35: 0 | I35: 0 | J35: 0 | K35: 0 | L35: 0 | M35: 0 | N35: 0 | O35: 0
A36: Financial Services | B36: Financial Services | C36: Finance | D36: 12 | E36: 12826.93 | F36: 11 | G36: 4710.9324 | H36: 1 | I36: 33.13 | J36: 2 | K36: 4271.8281 | L36: 4 | M36: 255.05 | N36: 4 | O36: 150.92432
C37: Banks | D37: 4 | E37: 2057.21 | F37: 1 | G37: 1151 | H37: 1 | I37: 1151 | J37: 0 | K37: 0 | L37: 0 | M37: 0 | N37: 0 | O37: 0
C38: Capital Markets | D38: 4 | E38: 914.39506 | F38: 0 | G38: 0 | H38: 0 | I38: 0 | J38: 0 | K38: 0 | L38: 0 | M38: 0 | N38: 0 | O38: 0
C39: Insurance | D39: 1 | E39: 1171.58 | F39: 1 | G39: 2614.6459 | H39: 0 | I39: 0 | J39: 1 | K39: 2614.6459 | L39: 0 | M39: 0 | N39: 0 | O39: 0
C40: Financial Technology (Fintech) | D40: 1 | E40: 49.96544 | F40: 0 | G40: 0 | H40: 0 | I40: 0 | J40: 0 | K40: 0 | L40: 0 | M40: 0 | N40: 0 | O40: 0
...

Sheet 8
A1: Table 8: Sector-wise and Region-wise Distribution of Capital Mobilised through Public and Rights Issues (Equity)
A2: Year / Month | B2: Total | D2: Sector-wise | H2: Region-wise
D3: Private | F3: Public | H3: Northern | J3: Eastern | L3: Western | N3: Southern | P3: Central
B4: No. of issues | C4: Amount ( ₹ crore) | D4: No. of issues | E4: Amount ( ₹ crore) | F4: No. of issues | G4: Amount ( ₹ crore) | H4: No. of issues | I4: Amount ( ₹ crore) | J4: No. of issues | K4: Amount ( ₹ crore) | L4: No. of issues | M4: Amount ( ₹ crore) | N4: No. of issues | O4: Amount ( ₹ crore) | P4: No. of issues | Q4: Amount ( ₹ crore)
A5: 2023-24 | B5: 340 | C5: 83091.976 | D5: 337 | E5: 80426.092 | F5: 2 | G5: 2639.41 | H5: 72 | I5: 32405.594 | J5: 16 | K5: 2306.4181 | L5: 195 | M5: 37193.108 | N5: 50 | O5: 10340.569 | P5: 7 | Q5: 846.28728
A6: 2024-25# | B6: =SUM(H6,J6,L6,N6,P6) -> 153 | C6: =SUM(I6,K6,M6,O6,Q6) -> 50231.449 | D6: =SUM(D7:D10) -> 153 | E6: =SUM(E7:E10) -> 50231.348 | F6: =SUM(F7:F10) -> 0 | G6: =SUM(G7:G10) -> 0 | H6: =SUM(H7:H10) -> 35 | I6: =SUM(I7:I10) -> 9782.3164 | J6: =SUM(J7:J10) -> 10 | K6: =SUM(K7:K10) -> 714.31996 | ... Q6: =SUM(Q7:Q10) -> 327.14495
A7: 45383 | B7: =SUM(H7,J7,L7,N7,P7) -> 35 | C7: =SUM(I7,K7,M7,O7,Q7) -> 25370.567 | D7: 35 | E7: 25370.567 | F7: 0 | G7: 0 | H7: 10 | I7: 4644.9489 | L7: 22 | M7: 19527.236 | N7: 3 | O7: 1198.3815
A8: =EOMONTH(A7,1) -> 45443 | B8: =SUM(H8,J8,L8,N8,P8) -> 38 | C8: =SUM(I8,K8,M8,O8,Q8) -> 12288.583 | D8: 38 | E8: 12288.583 | F8: 0 | G8: 0 | H8: 6 | I8: 2234.415 | J8: 3 | K8: 426.588 | L8: 22 | M8: 4558.1944 | N8: 6 | O8: 5026.225 | P8: 1 | Q8: 43.16112
A9: =EOMONTH(A8,1) -> 45473 | B9: =SUM(H9,J9,L9,N9,P9) -> 38 | C9: =SUM(I9,K9,M9,O9,Q9) -> 3571.198 | D9: 38 | E9: 3571.198 | F9: 0 | G9: 0 | H9: 7 | I9: 1299.5532 | J9: 3 | K9: 87.91 | L9: 25 | M9: 1581.0904 | N9: 2 | O9: 571.85 | P9: 1 | Q9: 30.7944
A10: =EOMONTH(A9,1) -> 45504 | B10: =SUM(H10,J10,L10,N10,P10) -> 42 | C10: =SUM(I10,K10,M10,O10,Q10) -> 9001.1009 | D10: 42 | E10: 9001 | F10: 0 | G10: 0 | H10: 12 | I10: 1603.3993 | J10: 4 | K10: 199.82196 | L10: 19 | M10: 4648.3602 | N10: 4 | O10: 2296.33 | P10: 3 | Q10: 253.18943
A11: Notes - From April 2020 onwards, data on IPO issues are categorised based on the listing date .
A12: ="# indicates as on "&TEXT('1'!$C$2,"mmmm dd, yyyy") -> # indicates as on July 31, 2024
A13: Source: SEBI.

Sheet 9
A1: Table 9: Size-wise Classification of Capital Raised through Public and Rights Issues (Equity)
A2: Year / Month | B2: Total | D2: < 5 crore | F2: ≥ 5crore - < 10crore | H2: ≥ 10 crore - < 50 crore | J2: ≥ 50 crore - < 100 crore | L2: ≥ 100 crore -<500 crore | N2: >=₹500 crore
B3: No. of issues | C3: Amount ( ₹ crore) | D3: No. of issues | E3: Amount ( ₹ crore) | F3: No. of issues | G3: Amount ( ₹ crore) | H3: No. of issues | I3: Amount ( ₹ crore) | J3: No. of issues | K3: Amount ( ₹ crore) | L3: No. of issues | M3: Amount ( ₹ crore) | N3: No. of issues | O3: Amount ( ₹ crore)
A4: 2023-24 | B4: 340 | C4: 83091.976 | D4: 3 | E4: 9.462 | F4: 28 | G4: 218.70822 | H4: 187 | I4: 5420.5137 | J4: 38 | K4: 2473.5783 | L4: 29 | M4: 8297.8354 | N4: 55 | O4: 66671.879
A5: 2024-25# | B5: =SUM(B6:B9) -> 153 | C5: =SUM(C6:C9) -> 50231.449 | D5: =SUM(D6:D9) -> 2 | E5: =SUM(E6:E9) -> 8.35 | F5: =SUM(F6:F9) -> 14 | G5: =SUM(G6:G9) -> 102.5336 | H5: =SUM(H6:H9) -> 89 | I5: =SUM(I6:I9) -> 2664.6198 | ... O5: =SUM(O6:O9) -> 42936.749
A6: 45383 | B6: =D6+F6+H6+J6+L6+N6 -> 35 | C6: =E6+G6+I6+K6+M6+O6 -> 25370.567 | D6: 1 | E6: 4.76 | F6: 3 | G6: 21.8 | H6: 20 | I6: 513.18407 | J6: 5 | K6: 275.15276 | L6: 2 | M6: 480.2 | N6: 4 | O6: 24075.47
A7: =EOMONTH(A6,1) -> 45443 | B7: =D7+F7+H7+J7+L7+N7 -> 38 | C7: =E7+G7+I7+K7+M7+O7 -> 12288.583 | D7: 0 | E7: 0 | F7: 4 | G7: 30.3656 | H7: 25 | I7: 709.34326 | J7: 1 | K7: 96.285 | L7: 2 | M7: 574.63107 | N7: 6 | O7: 10877.959
A8: =EOMONTH(A7,1) -> 45473 | B8: =D8+F8+H8+J8+L8+N8 -> 38 | C8: =E8+G8+I8+K8+M8+O8 -> 3571.198 | D8: 1 | E8: 3.59 | F8: 6 | G8: 41.368 | H8: 22 | I8: 736.90672 | J8: 2 | K8: 182.27328 | L8: 5 | M8: 1329.94 | N8: 2 | O8: 1277.12
A9: =EOMONTH(A8,1) -> 45504 | B9: =D9+F9+H9+J9+L9+N9 -> 42 | C9: =E9+G9+I9+K9+M9+O9 -> 9001.1009 | D9: 0 | E9: 0 | F9: 1 | G9: 9 | H9: 22 | I9: 705.18572 | J9: 7 | K9: 405.7052 | L9: 7 | M9: 1175.0099 | N9: 5 | O9: 6706.2
A10: Notes - From April 2020 onwards, data on IPO issues are categorised based on the listing date .
A11: ="# indicates as on "&TEXT('1'!$C$2,"mmmm dd, yyyy") -> # indicates as on July 31, 2024
A12: Source: SEBI.

Sheet 10
A1: Table 10: Capital Raised by Listed Companies from the Primary Market through QIPs
A2: Year / Month | B2: Only BSE | D2: Only NSE | F2: Only MSEI | H2: Common | J2: Total
B3: No. of issues | C3: Amount ( ₹ crore) | D3: No. of issues | E3: Amount ( ₹ crore) | F3: No. of issues | G3: Amount ( ₹ crore) | H3: No. of issues | I3: Amount ( ₹ crore) | J3: No. of issues | K3: Amount ( ₹ crore)
A4: 2023-24 | B4: 0 | C4: 0 | D4: 3 | E4: 266.53776 | F4: 0 | G4: 0 | H4: 58 | I4: 68704.954 | J4: 61 | K4: 68971.491
A5: 2024-25# | B5: =SUM(B6:B9) -> 0 | C5: =SUM(C6:C9) -> 0 | D5: =SUM(D6:D9) -> 1 | E5: =SUM(E6:E9) -> 24.84 | F5: =SUM(F6:F9) -> 0 | G5: =SUM(G6:G9) -> 0 | H5: =SUM(H6:H9) -> 29 | I5: =SUM(I6:I9) -> 30960.832 | ... K5: =SUM(K6:K9) -> 30985.672
A6: 45383 | B6: 0 | C6: 0 | D6: 0 | E6: 0 | F6: 0 | G6: 0 | H6: 11 | I6: 11471.733 | J6: =SUM(B6,D6,F6,H6) -> 11 | K6: =SUM(C6,E6,G6,I6) -> 11471.733
A7: =EOMONTH(A6,1) -> 45443 | B7: 0 | C7: 0 | D7: 0 | E7: 0 | F7: 0 | G7: 0 | H7: 2 | I7: 3039.9999 | J7: =SUM(B7,D7,F7,H7) -> 2 | K7: =SUM(C7,E7,G7,I7) -> 3039.9999
A8: =EOMONTH(A7,1) -> 45473 | B8: 0 | C8: 0 | D8: 1 | E8: 24.84 | F8: 0 | G8: 0 | H8: 5 | I8: 2749.9996 | J8: =SUM(B8,D8,F8,H8) -> 6 | K8: =SUM(C8,E8,G8,I8) -> 2774.8396
A9: =EOMONTH(A8,1) -> 45504 | B9: 0 | C9: 0 | D9: 0 | E9: 0 | F9: 0 | G9: 0 | H9: 11 | I9: 13699.1 | J9: =SUM(B9,D9,F9,H9) -> 11 | K9: =SUM(C9,E9,G9,I9) -> 13699.1
A10: Notes: 1. The above data includes both "no. of issues" and "Amount" raised on conversion of convertible securities issued on QIP basis.
A11: ="# indicates as on "&TEXT('1'!$C$2,"mmmm dd, yyyy") -> # indicates as on July 31, 2024
A12: Source: BSE, NSE and MSEI.

Sheet 11
A1: Table 11: Preferential Allotments Listed at BSE, NSE and MSEI
A2: Year/Month | B2: Only BSE | D2: Only NSE | F2: Only MSEI | H2: Common# | J2: Total
B3: No. of issues | C3: Amount ( ₹ crore) | D3: No. of issues | E3: Amount ( ₹ crore) | F3: No. of issues | G3: Amount ( ₹ crore) | H3: No. of issues | I3: Amount ( ₹ crore) | J3: No. of issues | K3: Amount ( ₹ crore)
A4: 2023-24 | B4: 354 | C4: 10393.32 | D4: 73 | E4: 1010.7464 | F4: 5 | G4: 41.44 | H4: 257 | I4: 33709.596 | J4: 689 | K4: 45155.102
A5: 2024-25# | B5: =SUM(B6:B9) -> 165 | C5: =SUM(C6:C9) -> 3538.91 | D5: =SUM(D6:D9) -> 58 | E5: =SUM(E6:E9) -> 698.09301 | F5: =SUM(F6:F9) -> 1 | G5: =SUM(G6:G9) -> 5.02 | H5: =SUM(H6:H9) -> 121 | I5: =SUM(I6:I9) -> 39772.764 | ... K5: =SUM(K6:K9) -> 44014.787
A6: 45383 | B6: 51 | C6: 1387.31 | D6: 13 | E6: 206.12993 | F6: 1 | G6: 5.02 | H6: 42 | I6: 6103.73 | J6: =B6+D6+F6+H6 -> 107 | K6: =C6+E6+G6+I6 -> 7702.1899
A7: =EOMONTH(A6,1) -> 45443 | B7: 56 | C7: 839.5 | D7: 20 | E7: 185.11948 | F7: 0 | G7: 0 | H7: 38 | I7: 23968.574 | J7: =B7+D7+F7+H7 -> 114 | K7: =C7+E7+G7+I7 -> 24993.193
A8: =EOMONTH(A7,1) -> 45473 | B8: 26 | C8: 822.4 | D8: 13 | E8: 187.0436 | F8: 0 | G8: 0 | H8: 22 | I8: 5985.75 | J8: =B8+D8+F8+H8 -> 61 | K8: =C8+E8+G8+I8 -> 6995.1936
A9: =EOMONTH(A8,1) -> 45504 | B9: 32 | C9: 489.7 | D9: 12 | E9: 119.8 | F9: 0 | G9: 0 | H9: 19 | I9: 3714.71 | J9: =B9+D9+F9+H9 -> 63 | K9: =C9+E9+G9+I9 -> 4324.21
A10: #Listed at any two or three exchanges.
A11: ="# indicates as on "&TEXT('1'!$C$2,"mmmm dd, yyyy") -> # indicates as on July 31, 2024
A12: Source: BSE, NSE and MSEI.

Sheet 12
A1: Table 12: Private Placement of Corporate Debt listed at BSE and NSE
A2: Year/Month | B2: Only NSE | D2: Only BSE | F2: Both NSE and BSE | H2: Total
B3: No. of issues | C3: Amount ( ₹ crore) | D3: No. of issues | E3: Amount ( ₹ crore) | F3: No. of issues | G3: Amount ( ₹ crore) | H3: No. of issues | I3: Amount ( ₹ crore)
A4: 2023-24 | B4: 288 | C4: 255227.82 | D4: 945 | E4: 297407.27 | F4: 114 | G4: 285120.45 | H4: 1347 | I4: 837755.55
A5: 2024-25# | B5: =SUM(B6:B9) -> 93 | C5: =SUM(C6:C9) -> 80767.334 | D5: =SUM(D6:D9) -> 355 | E5: =SUM(E6:E9) -> 96382.75 | F5: =SUM(F6:F9) -> 42 | G5: =SUM(G6:G9) -> 72924.671 | H5: =SUM(H6:H9) -> 490 | I5: =SUM(I6:I9) -> 250074.75
A6: 45383 | B6: 11 | C6: 9221.6 | D6: 83 | E6: 14558 | F6: 7 | G6: 6728 | H6: =SUM(B6,D6,F6) -> 101 | I6: =SUM(C6,E6,G6) -> 30507.6
A7: =EOMONTH(A6,1) -> 45443 | B7: 25 | C7: 20114 | D7: 89 | E7: 30261 | F7: 9 | G7: 10852 | H7: 123 | I7: 61227
A8: =EOMONTH(A7,1) -> 45473 | B8: 27 | C8: 18962.734 | D8: 95 | E8: 22087.75 | F8: 9 | G8: 23246.671 | H8: =SUM(B8,D8,F8) -> 131 | I8: =SUM(C8,E8,G8) -> 64297.155
A9: =EOMONTH(A8,1) -> 45504 | B9: 30 | C9: 32469 | D9: 88 | E9: 29476 | F9: 17 | G9: 32098 | H9: =SUM(B9,D9,F9) -> 135 | I9: =SUM(C9,E9,G9) -> 94043
A10: ="# indicates as on "&TEXT('1'!$C$2,"mmmm dd, yyyy") -> # indicates as on July 31, 2024
A11: Source: BSE and NSE

Sheet 13(Old)
A1: Table 13: Trends in Settled Trades in the Corporate Debt Market
A2: Year / Month | B2: ICCL | D2: NSCCL | F2: MSE Clearing | H2: Total
B3: No. of Trades | C3: Value (₹ crore) | D3: No. of Trades | E3: Value (₹ crore) | F3: No. of Trades | G3: Value (₹ crore) | H3: No. of Trades | I3: Value (₹ crore)
A4: 2023-24 | B4: 129879 | C4: 204122.94 | D4: 83338 | E4: 1113679.3 | F4: 0 | G4: 0 | H4: 213217 | I4: 1317802.3
A5: 2024-25# | B5: =SUM(B6:B9) -> 46686 | C5: =SUM(C6:C9) -> 130624.89 | D5: =SUM(D6:D9) -> 48725 | E5: =SUM(E6:E9) -> 338280.2 | F5: =SUM(F6:F9) -> 0 | G5: =SUM(G6:G9) -> 0 | H5: =SUM(H6:H9) -> 95411 | I5: =SUM(I6:I9) -> 468905.09
A6: 45383 | B6: 12695 | C6: 81929.179 | D6: 10338 | E6: 12366.45 | F6: 0 | G6: 0 | H6: =SUM(B6+D6+F6) -> 23033 | I6: =SUM(C6+E6+G6) -> 94295.629
A7: 45413 | B7: 11147 | C7: 16078.74 | D7: 12473 | E7: 107641 | F7: 0 | G7: 0 | H7: =SUM(B7+D7+F7) -> 23620 | I7: =SUM(C7+E7+G7) -> 123719.74
A8: 45444 | B8: 10097 | C8: 16453.703 | D8: 12153 | E8: 97991.476 | F8: 0 | G8: 0 | H8: 22250 | I8: 114445.18
A9: 45474 | B9: 12747 | C9: 16163.268 | D9: 13761 | E9: 120281.27 | F9: 0 | G9: 0 | H9: =SUM(B9,D9) -> 26508 | I9: =SUM(C9,E9) -> 136444.54
A11: This table has been revised to include only settled trades (OTC+RFQ trades) through exchange platform.
A12: ="# indicates as on "&TEXT('1'!$C$2,"mmmm dd, yyyy") -> # indicates as on July 31, 2024
A13: Source: ICCL, NSCCL and MSE Clearing.

Sheet 13 
A1: Table 13: Trends in Settled Trades in the Corporate Debt Market
A2: Year / Month | B2: BSE/ICCL [Trades executed on OTC+RFQ+anonymous platforms and settled through ICCL] | F2: NSE/NSCCL [Trades executed on OTC+RFQ+anonymous platforms and settled through NSCCL] | J2: MCX-SX/MSE Clearing | L2: Off Market Settled Trades | P2: Total Trades Settled
B3: Listed Corporate Bonds | D3: Unlisted Corporate Bonds | F3: Listed Corporate Bonds | H3: Unlisted Corporate Bonds | L3: Listed Corporate Bonds | N3: Unlisted Corporate Bonds
B4: No. of Trades Settled | C4: Amount (₹ crore) | D4: No. of Trades Settled | E4: Amount (₹ crore) | F4: No. of Trades Settled | G4: Amount (₹ crore) | H4: No. of Trades Settled | I4: Amount (₹ crore) | J4: No. of Trades Settled | K4: Amount (₹ crore) | L4: No. of Trades Settled | M4: Amount (₹ crore) | N4: No. of Trades Settled | O4: Amount (₹ crore) | P4: No. of Trades Settled | Q4: Amount (₹ crore)
A5: 2023-24 | B5: 339906 | C5: 140568.51 | D5: 22123 | E5: 66811.26 | F5: 751149 | G5: 1078970.8 | H5: 10683 | I5: 39274.17 | J5: 0 | K5: 0 | L5: 132578 | M5: 18900.33 | N5: 34998 | O5: 28868.97 | P5: 1291437 | Q5: 1373394
A6: 2024-25# | B6: =SUM(B7:B10) -> 105807 | C6: =SUM(C7:C10) -> 38701.545 | D6: =SUM(D7:D10) -> 7992 | E6: =SUM(E7:E10) -> 23637.759 | F6: =SUM(F7:F10) -> 243625 | G6: =SUM(G7:G10) -> 393355.68 | H6: =SUM(H7:H10) -> 2188 | I6: =SUM(I7:I10) -> 16584.408 | ... Q6: =SUM(Q7:Q10) -> 487972.69
A7: 45383 | B7: 25903 | C7: 7415.307 | D7: 1977 | E7: 5249.342 | F7: 64127 | G7: 78200.87 | H7: 610 | I7: 4241.988 | J7: 0 | K7: 0 | L7: 2555 | M7: 1011.408 | N7: 2836 | O7: 2708.523 | P7: 98008 | Q7: 98827.44
A8: 45413 | B8: 27094 | C8: 10486.48 | D8: 2124 | E8: 5852.266 | F8: 61350 | G8: 101645.8 | H8: 582 | I8: 6548.765 | J8: 0 | K8: 0 | L8: 2280 | M8: 915.9349 | N8: 2479 | O8: 4802.771 | P8: 95909 | Q8: 130252
A9: 45444 | B9: 24202 | C9: 11080.92 | D9: 1708 | E9: 5762.829 | F9: 54517 | G9: 95480.17 | H9: 474 | I9: 3057.867 | J9: 0 | K9: 0 | L9: 1669 | M9: 733.383 | N9: 2562 | O9: 2355.499 | P9: 85132 | Q9: 118470.7
A10: 45474 | B10: 28608 | C10: 9718.8383 | D10: 2183 | E10: 6773.3219 | F10: 63631 | G10: 118028.84 | H10: 522 | I10: 2735.7883 | J10: 0 | K10: 0 | L10: 1949 | M10: 940.16476 | N10: 3130 | O10: 2225.5903 | P10: 100023 | Q10: 140422.55
A11: # indicates as on July 31, 2024
A12: Source: ICCL, NSCCL, MSE Clearing, NSDL and CDSL.

Sheet 14
A1: Table 14: Ratings Assigned for Long-term Corporate Debt Securities (Maturity ≥ 1 year)
A2: Grade | B2: Investment Grade | J2: Non-Investment Grade | L2: Total
B3: Highest Safety (AAA) | D3: High Safety (AA) | F3: Adequate Safety (A) | H3: Moderate Safety (BBB)
A4: Period | B4: No. of issues | C4: Amount ( ₹ crore) | D4: No. of issues | E4: Amount ( ₹ crore) | F4: No. of issues | G4: Amount ( ₹ crore) | H4: No. of issues | I4: Amount ( ₹ crore) | J4: No. of issues | K4: Amount ( ₹ crore) | L4: No. of issues | M4: Amount ( ₹ crore)
A5: 2022-23 | B5: 266 | C5: 2019875.8 | D5: 409 | E5: 372534.52 | F5: 372 | G5: 61654.9 | H5: 200 | I5: 18194.87 | J5: 72 | K5: 17535.12 | L5: 1319 | M5: 2489794.7
A6: 2023-24$ | B6: =SUM(B7:B10) -> 127 | C6: =SUM(C7:C10) -> 1269289.9 | D6: =SUM(D7:D10) -> 165 | E6: =SUM(E7:E10) -> 153963.38 | F6: =SUM(F7:F10) -> 129 | G6: =SUM(G7:G10) -> 20557.36 | H6: =SUM(H7:H10) -> 62 | I6: =SUM(I7:I10) -> 20601.65 | ... M6: =SUM(M7:M10) -> 1470285.3
A7: Apr-23 | B7: 16 | C7: 96343.84 | D7: 21 | E7: 8364.25 | F7: 25 | G7: 920.49 | H7: 10 | I7: 1702.58 | J7: 3 | K7: 554 | L7: 75 | M7: 107885.16
A8: May-23 | B8: 29 | C8: 188112.1 | D8: 44 | E8: 27924.79 | F8: 20 | G8: 2802.42 | H8: 24 | I8: 1864.45 | J8: 10 | K8: 4900 | L8: 127 | M8: 225603.76
A9: Jun-23 | B9: 40 | C9: 292428.78 | D9: 64 | E9: 71403.79 | F9: 50 | G9: 9645.95 | H9: 19 | I9: 16207.8 | J9: 2 | K9: 275 | L9: 175 | M9: 389961.32
A10: Jul-23 | B10: 42 | C10: 692405.2 | D10: 36 | E10: 46270.55 | F10: 34 | G10: 7188.5 | H10: 9 | I10: 826.82 | J10: 4 | K10: 144 | L10: 125 | M10: 746835.07
A11: $ indicates upto July 31, 2023
A12: This data is provisonal
A13: Note: Data in the table may include ratings of a single company from multiple credit rating agencies across rating categories.
A14: Source: Credit Rating Agencies.

Sheet 15
A1: Table 15: Review of Accepted Ratings of Corporate Debt Securities (Maturity ≥ 1 year)
A2: Grade | B2: Upgraded | D2: Downgraded | F2: Reaffirmed | H2: Rating Watch | J2: Withdrawn/ Suspended
A3: Period | B3: No. of issues | C3: Amount ( ₹ crore) | D3: No. of issues | E3: Amount ( ₹ crore) | F3: No. of issues | G3: Amount ( ₹ crore) | H3: No. of issues | I3: Amount ( ₹ crore) | J3: No. of issues | K3: Amount ( ₹ crore)
A4: 2022-23 | B4: 460 | C4: 269687.23 | D4: 251 | E4: 107880.65 | F4: 7153 | G4: 18110493 | H4: 135 | I4: 34838.31 | J4: 1041 | K4: 454662.93
A5: 2023-24$ | B5: =SUM(B6:B9) -> 266 | C5: =SUM(C6:C9) -> 120177.51 | D5: =SUM(D6:D9) -> 70 | E5: =SUM(E6:E9) -> 24472.11 | F5: =SUM(F6:F9) -> 2671 | G5: =SUM(G6:G9) -> 8792511.6 | H5: =SUM(H6:H9) -> 58 | I5: =SUM(I6:I9) -> 18517.46 | J5: =SUM(J6:J9) -> 465 | K5: 846860.18
A6: Apr-23 | B6: 17 | C6: 6525.88 | D6: 16 | E6: 4839.68 | F6: 563 | G6: 1938191.2 | H6: 36 | I6: 13100 | J6: 77 | K6: 48942.77
A7: May-23 | B7: 101 | C7: 67452.92 | D7: 21 | E7: 8500.23 | F7: 584 | G7: 2215716.1 | H7: 12 | I7: 2298 | J7: 96 | K7: 41223.2
A8: Jun-23 | B8: 113 | C8: 30889.09 | D8: 12 | E8: 3333 | F8: 878 | G8: 2381727.5 | H8: 3 | I8: 850 | J8: 150 | K8: 65287.715
A9: Jul-23 | B9: 35 | C9: 15309.62 | D9: 21 | E9: 7799.2 | F9: 646 | G9: 2256876.7 | H9: 7 | I9: 2269.46 | J9: 142 | K9: 691406.49#
A10: $ indicates upto July 31, 2023
A11: This data is provisonal
A12: # The increase in the amount for rated quantum for withdrawals from previous trends is due to merger of Housing Development Finance Corporation Limited (HDFC) and HDFC Bank Limited (HDFC Bank) where the instruments of HDFC were withdrawn post-merger and the same were transferred to HDFC Bank.
A13: Note: Data in the table may include ratings of a single company from multiple credit rating agencies across rating categories.
A14: Source: Credit Rating Agencies.

Sheet 16
A1: Table 16: Distribution of Turnover on Cash Segments of Stock Exchanges (`crore)
A2: Stock Exchanges | B2: 2023-24 | C2: 2024-25$ | D2: July-24
A3: BSE | B3: 1629038.3 | C3: 784509.36 | D3: 235148.12
A4: MSEI | B4: 29.33808 | C4: 2.0832373 | D4: 0.51822155
A5: NSE | B5: 20103439 | C5: 10554940 | D5: 3061576.7
A7: Includes exchange traded turnnover in corporate bonds
A8: ="$ indicates as on "&TEXT('1'!$C$2,"mmmm dd, yyyy") -> $ indicates as on July 31, 2024
A9: Source: BSE, NSE and MSEI.

Sheet 17
A1: Table 17: Trends in Cash Segment of BSE
A2: Year / Month | B2: No. of Companies Listed | C2: No. of Companies Permitted | D2: No. of Companies Traded | E2: No. of Trading Days | F2: No. of Trades (Lakh) | G2: Traded Quantity (Lakh) | H2: Turnover (` crore) | I2: Average Daily Turnover (` crore) | J2: Average Trade Size (`) | K2: Demat Securities Traded (Lakh) | L2: Demat Turnover (` crore) | M2: Market Capitalisation (` crore) | N2: S&P BSE Sensex
N3: High | O3: Low | P3: Close
A4: 2023-24 | B4: 5252 | C4: 25 | D4: 4295 | E4: 246 | F4: 8263.45 | G4: 2120712.3 | H4: 1629038.3 | I4: 6622.1071 | J4: 19713.78 | K4: 2120712.3 | L4: 1629038.2 | M4: 38697100 | N4: 74245.17 | O4: 58793.08 | P4: 73651.35
A5: 2024-25$ | B5: =INDEX(B6:B17,COUNT(B6:B17)) -> 5307 | C5: =INDEX(C6:C17,COUNT(C6:C17)) -> 26 | D5: 4265 | E5: =SUM(E6:E17) -> 83 | F5: =SUM(F6:F17) -> 3928.19 | G5: =SUM(G6:G17) -> 808654.08 | H5: =SUM(H6:H17) -> 784509.36 | I5: =H5/E5 -> 9451.92 | J5: =H5/F5*100 -> 19971.268 | K5: =SUM(K6:K17) -> 808654.08 | L5: =SUM(L6:L17) -> 784509.32 | M5: =INDEX(M6:M17,COUNT(M6:M17)) -> 46238008 | N5: =MAX(N6:N17) -> 81908.43 | O5: =MIN(O6:O17) -> 70234.43 | P5: =INDEX(P6:P17,COUNT(P6:P17)) -> 81741.34
A6: 45383 | B6: 5264 | C6: 26 | D6: 4153 | E6: 20 | F6: 766.49 | G6: 188397.56 | H6: 152767.43 | I6: 7638.3715 | J6: 19930.779 | K6: 188397.56 | L6: 152767.43 | M6: 40655852 | N6: 75111.39 | O6: 74346.4 | P6: 74482.78
A7: 45413 | B7: 5274 | C7: 26 | D7: 4170 | E7: 22 | F7: 871.14 | G7: 176258.29 | H7: 169592.24 | I7: 7708.7382 | J7: 19467.851 | K7: 176258.29 | L7: 169592.23 | M7: 41212881 | N7: 76009.68 | O7: 71866.01 | P7: 73961.31
A8: 45444 | B8: 5293 | C8: 26 | D8: 4200 | E8: 19 | F8: 1080.27 | G8: 201461 | H8: 227001.57 | I8: =H8/E8 -> 11947.451 | J8: =100*H8/F8 -> 21013.411 | K8: 201461 | L8: 227001.56 | M8: 43924744 | N8: 79671.58 | O8: 70234.43 | P8: 79032.73
A9: 45474 | B9: 5307 | C9: 26 | D9: 4208 | E9: 22 | F9: 1210.29 | G9: 242537.23 | H9: 235148.12 | I9: 10688.551 | J9: 19429.072 | K9: 242537.23 | L9: 235148.1 | M9: 46238008 | N9: 81908.43 | O9: 78971.79 | P9: 81741.34
A10: 45505
A11: 45536
A12: 45566
A13: 45597
A14: 45627
A15: 45658
A16: 45689
A17: 45717
A19: Note : No. of Companies Listed with BSE includes count of both active and suspended companies.
A20: No.of trades and turnover details inclusive of exchange traded corporate bonds
A21: Source: BSE
A22: ="$ indicates as on "&TEXT('1'!$C$2,"mmmm dd, yyyy") -> $ indicates as on July 31, 2024

Sheet 18
A1: Table 18: Trends in Cash Segment of NSE
A2: Year / Month | B2: No. of Companies Listed | C2: No. of Companies Permitted | D2: No. of companies Traded# | E2: No. of Trading Days | F2: No. of Trades (Lakh) | G2: Traded Quantity (Lakh) | H2: Turnover (` crore) | I2: Average Daily Turnover (` crore) | J2: Average Trade Size (`) | K2: Demat Securities Traded (Lakh) | L2: Demat Turnover (` crore) | M2: Market Capitalisation (` crore) | N2: Nifty 50 Index
N3: High | O3: Low | P3: Close
A4: 2023-24 | B4: 2439 | C4: 3 | D4: 2985 | E4: 246 | F4: 68124.68 | G4: 10179861 | H4: 20103439 | I4: 81721.298 | J4: 29509.774 | K4: 10179861 | L4: 20103439 | M4: 38421668 | N4: 22526.6 | O4: 17312.75 | P4: 22326.9
A5: 2024-25$ | B5: =INDEX(B6:B17,COUNT(B6:B17)) -> 2529 | C5: =INDEX(C6:C17,COUNT(C6:C17)) -> 3 | D5: 3294 | E5: =SUM(E6:E17) -> 83 | F5: =SUM(F6:F17) -> 33050.75 | G5: =SUM(G6:G17) -> 4258187.4 | H5: =SUM(H6:H17) -> 10554940 | I5: =H5/E5 -> 127167.95 | J5: =H5/F5*100 -> 31935.554 | K5: =SUM(K6:K17) -> 4258187.4 | L5: =SUM(L6:L17) -> 10554940 | M5: =INDEX(M6:M17,COUNT(M6:M17)) -> 45865878 | N5: =MAX(N6:N17) -> 24999 | O5: =MIN(O6:O17) -> 21281.45 | P5: =INDEX(P6:P17,COUNT(P6:P17)) -> 24951
A6: 45383 | B6: 2464 | C6: 3 | D6: 2625 | E6: 20 | F6: 6810.19 | G6: 990584.38 | H6: 2120195.5 | I6: 106009.78 | J6: 31132.69 | K6: 990584.38 | L6: 2120195.5 | M6: 40304406 | N6: 22526.6 | O6: 21710.2 | P6: 22604.85
A7: 45413 | B7: 2482 | C7: 3 | D7: 2995 | E7: 22 | F7: 7680.33 | G7: 924888.14 | H7: 2467941.4 | I7: 112179.16 | J7: 32133.27 | K7: 924888.14 | L7: 2467941.4 | M7: 40880530 | N7: 23110.8 | O7: 21821.05 | P7: 22530.7
A8: 45444 | B8: 2499 | C8: 3 | D8: 2998 | E8: 19 | F8: 8709.81 | G8: 1157608.4 | H8: 2905226.5 | I8: 152906.66 | J8: 33355.8 | K8: 1157608.4 | L8: 2905226.5 | M8: 43573919 | N8: 24174 | O8: 21281.45 | P8: 24010.6
A9: 45474 | B9: 2529 | C9: 3 | D9: 3093 | E9: 22 | F9: 9850.42 | G9: 1185106.6 | H9: 3061576.7 | I9: 139162.58 | J9: 31080.67 | K9: 1185106.6 | L9: 3061576.7 | M9: 45865878 | N9: 24999 | O9: 23992 | P9: 24951
A10: 45505
A11: 45536
A12: 45566
A13: 45597
A14: 45627
A15: 45658
A16: 45689
A17: 45717
A19: Turnover Data compiled for all markets except auction market
A20: No.of trades and turnover details inclusive of exchange traded corporate bonds
A21: #Data for No. of companies traded includes Government securities, Corporate bonds, REITs, InvITs, NSE listed companies as well as “Permitted to Trade” companies but excludes ETFs & Mutual Funds
A22: Source: NSE
A23: $ indicates as on July 31, 2024

Sheet 19
A1: Table 19: Trends in Cash Segment of MSEI
A2: Year/Month | B2: No. of Companies Listed | C2: No. of Companies Permitted # | D2: No. of Companies Traded | E2: No. of Trading Days | F2: No. of Trades (Lakh) | G2: Traded Quantity (Lakh) | H2: Turnover (₹ crore) | I2: Average Daily Turnover (₹ crore) | J2: Average Trade Size (₹) | K2: Demat Securities Traded (Lakh) | L2: Demat Turnover (₹ crore) | M2: Market Capitalisation (₹ crore) | N2: SX 40 Index
N3: High | O3: Low | P3: Close
A4: 2023-24 | B4: 266 | C4: 1705 | D4: 10 | E4: 246 | F4: 0.00351 | G4: 20.22445 | H4: 29.33808 | I4: 0.11926049 | J4: 835842.73 | K4: NA | L4: NA | M4: 38356305 | N4: 42685.19 | O4: 33552.3 | P4: 42417.24
A5: 2024-25$ | B5: =INDEX(B6:B17,COUNT(B6:B17)) -> 266 | C5: 1771 | D5: 6 | E5: =SUM(E6:E17) -> 83 | F5: =SUM(F6:F17) -> 0.00148 | G5: =SUM(G6:G17) -> 7.63158 | H5: =SUM(H6:H17) -> 2.0832373 | I5: =H5/E5 -> 0.025099245 | J5: =H5/F5*100 -> 140759.28 | K5: NA | L5: NA | M5: =INDEX(M6:M17,COUNT(M6:M17)) -> 47610230 | N5: =MAX(N6:N17) -> 47309.14 | O5: =MIN(O6:O17) -> 41588.01 | P5: =INDEX(P6:P17,COUNT(P6:P17)) -> 47309.14
A6: 45383 | B6: 266 | C6: 1704 | D6: 1 | E6: 20 | F6: 0.00023 | G6: 0.76 | H6: 0.56713575 | I6: 0.028356787 | J6: 246580.76 | K6: NA | L6: NA | M6: 40187325 | N6: 43265.36 | O6: 41843.95 | P6: 42994.7
A7: 45413 | B7: 266 | C7: 1771 | D7: 2 | E7: 22 | F7: 0.00036 | G7: 0.96832 | H7: 0.7316605 | I7: 0.033257295 | J7: 203239.03 | K7: NA | L7: NA | M7: 41477460 | N7: 43643.65 | O7: 41779.14 | P7: 42784.29
A8: 45444 | B8: 266 | C8: 1840 | D8: 5 | E8: 19 | F8: 0.00062 | G8: 0.8376 | H8: 0.2662195 | I8: 0.014011553 | J8: 42938.629 | K8: NA | L8: NA | M8: 45649188 | N8: 45764.87 | O8: 41588.01 | P8: 45686.35
A9: 45474 | B9: 266 | C9: 1837 | D9: 5 | E9: 22 | F9: 0.00027 | G9: 5.06566 | H9: 0.51822155 | I9: 0.023555525 | J9: 191933.91 | K9: NA | L9: NA | M9: 47610230 | N9: 47309.14 | O9: 45686.35 | P9: 47309.14
A10: 45505
A11: 45536
A12: 45566
A13: 45597
A14: 45627
A15: 45658
A16: 45689
A17: 45717
A19: Note: Data of the Market Capitalisation is provided for all listed as well as permitted companies
A20: # Details of no. of companies in "permitted to trade" category which are active.
A21: Source: MSEI
A22: $ indicates as on July 31, 2024

Sheet 20
A1: Table 20: City-wise Distribution of Turnover on Cash Segments of BSE and NSE
A2: (Percentage share in Turnover)
A3: S.No | B3: City | C3: BSE | E3: NSE | G3: MSEI*
C4: 2024-25$ | D4: Jul-24 | E4: 2024-25$ | F4: Jul-24 | G4: 2024-25$ | H4: Jul-24
A5: 1 | B5: Ahmedabad | C5: 25.58827 | D5: 26.062039 | E5: 16.51 | F5: 16.95 | G5: 0 | H5: 0
A6: 2 | B6: Bengaluru | C6: 0.44146043 | D6: 0.6119869 | E6: 2.56 | F6: 3.17 | G6: 0 | H6: 0
A7: 3 | B7: Vadodara | C7: 0.28246984 | D7: 0.23485625 | E7: 0.1 | F7: 0.11 | G7: 0 | H7: 0
A8: 4 | B8: Bhubneshwar | C8: 0.0040490916 | D8: 0.0056969959 | E8: 0 | F8: 0 | G8: 0 | H8: 0
A9: 5 | B9: Chennai | C9: 0.30266644 | D9: 0.33330778 | E9: 1.11 | F9: 1.2 | G9: 0 | H9: 0
A10: 6 | B10: Ernakulam | C10: 0.035699145 | D10: 0.020602842 | E10: 0.29 | F10: 0.28 | G10: 0 | H10: 0
A11: 7 | B11: Coimbatore | C11: 0.011945768 | D11: 0.012294046 | E11: 0.05 | F11: 0.05 | G11: 0 | H11: 0
A12: 8 | B12: New Delhi | C12: 0.9405318 | D12: 0.92907138 | E12: 2.24 | F12: 2.2 | G12: 47.2 | H12: 37.7
A13: 9 | B13: Guwahati | C13: 0.023607484 | D13: 0.024401052 | E13: 0 | F13: 0 | G13: 0 | H13: 0
A14: 10 | B14: Hyderabad | C14: 0.11772091 | D14: 0.1153468 | E14: 2.77 | F14: 2.72 | G14: 0 | H14: 0
A15: 11 | B15: Indore | C15: 0.30734199 | D15: 0.30110064 | E15: 0.2 | F15: 0.19 | G15: 0 | H15: 0
A16: 12 | B16: Jaipur | C16: 0.4207859 | D16: 0.31172268 | E16: 0.17 | F16: 0.15 | G16: 0 | H16: 0
... A25: 21 | B25: Others | C25: 36.754612 | D25: 37.549904 | E25: 7.71 | F25: 7.76 | G25: 52.8 | H25: 62.3
B26: Total | C26: =SUM(C5:C25) -> 100 | D26: =SUM(D5:D25) -> 100 | E26: =SUM(E5:E25) -> 100 | F26: =SUM(F5:F25) -> 99.91 | G26: =SUM(G5:G25) -> 100 | H26: =SUM(H5:H25) -> 100
A28: Notes:
A29: *The city-wise distribution of turnover is based on the cities uploaded in the UCC database of the Exchange for clientele trades and members registered office city for proprietary trades.
A30: Source: BSE, NSE and MSEI.
A31: $ indicates as on July 31, 2024

Sheet 21
A1: Table 21: Category-wise Share of Turnover in Cash Segment of BSE
A2: Year / Month | B2: Percentage Share in Turnover
B3: Proprietary | C3: FPIs | D3: Mutual Funds | E3: Banks | F3: Others
A4: 2023-24 | B4: 34.431982 | C4: 13.019998 | D4: 3.2849059 | E4: 0.13515121 | F4: 49.127962
A5: 2024-25$ | B5: 37.815799 | C5: 6.2775898 | D5: 3.3773526 | E5: 0.0573724 | F5: 52.471886
A6: 45383 | B6: 38.581507 | C6: 6.1647818 | D6: 2.7451591 | E6: 0.0056915566 | F6: 52.50286
A7: 45413 | B7: 38.793481 | C7: 6.4085656 | D7: 3.7494118 | E7: 0.16447709 | F7: 50.884064
